Workbook

Sheet Study Checklist
A1: STUDY CHECKLIST — pick your study type, then complete only the sections shown | Q1: Sections for this selection
A2: Select Study Type / Service Line: | H2: =IF($D$2="","Select a study type to begin",IF(COUNTIF(N3:N136,"Not Ready")=0,"READY TO PROCEED","NOT READY — items still open")) -> Select a study type to begin | Q2: Section | R2: Show for selection?
A3: Folder Processing Checklist | L3: Status | Q3: Folder Processing Checklist | R3: =IF($D$2="","(select study type)",IFERROR(INDEX(Configuration!$C$3:$C$200,MATCH($D$2&"|"&Q3,Configuration!$F$3:$F$200,0)),"—")) -> (select study type) | S3: Folder Processing Checklist | T3: =IFERROR(INDEX($W$3:$W$19,MATCH($S3,$V$3:$V$19,0)),TRUE()) -> TRUE | V3: Folder Processing Checklist | W3: =IF($D$2="",TRUE(),IFERROR(INDEX(Configuration!$C$3:$C$200,MATCH($D$2&"|"&V3,Configuration!$F$3:$F$200,0))<>"No",TRUE())) -> TRUE
A4: Required Documents in Final Folder | L4: Done | M4: N/A | Q4: AX Processing Checklist | R4: =IF($D$2="","(select study type)",IFERROR(INDEX(Configuration!$C$3:$C$200,MATCH($D$2&"|"&Q4,Configuration!$F$3:$F$200,0)),"—")) -> (select study type) | S4: Folder Processing Checklist | T4: =IFERROR(INDEX($W$3:$W$19,MATCH($S4,$V$3:$V$19,0)),TRUE()) -> TRUE | V4: AX Processing Checklist | W4: =IF($D$2="",TRUE(),IFERROR(INDEX(Configuration!$C$3:$C$200,MATCH($D$2&"|"&V4,Configuration!$F$3:$F$200,0))<>"No",TRUE())) -> TRUE
A5: 1 | B5: Copy of Quotation (Final Version) | M5: =IF(NOT($T5),"☑","☐") -> ☐ | N5: =IF(NOT($T5),"N/A",IF($O5=TRUE(),"Ready","Not Ready")) -> Not Ready | Q5: CT/CST Check | R5: =IF($D$2="","(select study type)",IFERROR(INDEX(Configuration!$C$3:$C$200,MATCH($D$2&"|"&Q5,Configuration!$F$3:$F$200,0)),"—")) -> (select study type) | S5: Folder Processing Checklist | T5: =IFERROR(INDEX($W$3:$W$19,MATCH($S5,$V$3:$V$19,0)),TRUE()) -> TRUE | V5: CT/CST Check | W5: =IF($D$2="",TRUE(),IFERROR(INDEX(Configuration!$C$3:$C$200,MATCH($D$2&"|"&V5,Configuration!$F$3:$F$200,0))<>"No",TRUE())) -> TRUE
A6: 2 | B6: Copy of Formal Approval (PO, signed quote/SOW, CC or eCOM order email). | M6: =IF(NOT($T6),"☑","☐") -> ☐ | N6: =IF(NOT($T6),"N/A",IF($O6=TRUE(),"Ready","Not Ready")) -> Not Ready | Q6: Document Processing Checklist | R6: =IF($D$2="","(select study type)",IFERROR(INDEX(Configuration!$C$3:$C$200,MATCH($D$2&"|"&Q6,Configuration!$F$3:$F$200,0)),"—")) -> (select study type) | S6: Folder Processing Checklist | T6: =IFERROR(INDEX($W$3:$W$19,MATCH($S6,$V$3:$V$19,0)),TRUE()) -> TRUE | V6: Document Processing Checklist | W6: =IF($D$2="",TRUE(),IFERROR(INDEX(Configuration!$C$3:$C$200,MATCH($D$2&"|"&V6,Configuration!$F$3:$F$200,0))<>"No",TRUE())) -> TRUE
B7: If formal approval is a signed quote or SOW: | Q7: Purchase Order Check | R7: =IF($D$2="","(select study type)",IFERROR(INDEX(Configuration!$C$3:$C$200,MATCH($D$2&"|"&Q7,Configuration!$F$3:$F$200,0)),"—")) -> (select study type) | S7: Folder Processing Checklist | T7: =IFERROR(INDEX($W$3:$W$19,MATCH($S7,$V$3:$V$19,0)),TRUE()) -> TRUE | V7: Purchase Order Check | W7: =IF($D$2="",TRUE(),IFERROR(INDEX(Configuration!$C$3:$C$200,MATCH($D$2&"|"&V7,Configuration!$F$3:$F$200,0))<>"No",TRUE())) -> TRUE
B8: CS has confirmed with client that NO PO will be required. | M8: =IF(NOT($T8),"☑","☐") -> ☐ | N8: =IF(NOT($T8),"N/A",IF($O8=TRUE(),"Ready","Not Ready")) -> Not Ready | Q8: Compound Submission Form Check | R8: =IF($D$2="","(select study type)",IFERROR(INDEX(Configuration!$C$3:$C$200,MATCH($D$2&"|"&Q8,Configuration!$F$3:$F$200,0)),"—")) -> (select study type) | S8: Folder Processing Checklist | T8: =IFERROR(INDEX($W$3:$W$19,MATCH($S8,$V$3:$V$19,0)),TRUE()) -> TRUE | V8: Compound Submission Form Check | W8: =IF($D$2="",TRUE(),IFERROR(INDEX(Configuration!$C$3:$C$200,MATCH($D$2&"|"&V8,Configuration!$F$3:$F$200,0))<>"No",TRUE())) -> TRUE
B9: The relevant e-mail has been saved to study folder titled "Attn Finance". | M9: =IF(NOT($T9),"☑","☐") -> ☐ | N9: =IF(NOT($T9),"N/A",IF($O9=TRUE(),"Ready","Not Ready")) -> Not Ready | Q9: Study Details Check | R9: =IF($D$2="","(select study type)",IFERROR(INDEX(Configuration!$C$3:$C$200,MATCH($D$2&"|"&Q9,Configuration!$F$3:$F$200,0)),"—")) -> (select study type) | S9: Folder Processing Checklist | T9: =IFERROR(INDEX($W$3:$W$19,MATCH($S9,$V$3:$V$19,0)),TRUE()) -> TRUE | V9: Study Details Check | W9: =IF($D$2="",TRUE(),IFERROR(INDEX(Configuration!$C$3:$C$200,MATCH($D$2&"|"&V9,Configuration!$F$3:$F$200,0))<>"No",TRUE())) -> TRUE
B10: If PO is NEVER REQUIRED: eLIMs Client Specification has been created. | M10: =IF(NOT($T10),"☑","☐") -> ☐ | N10: =IF(NOT($T10),"N/A",IF($O10=TRUE(),"Ready","Not Ready")) -> Not Ready | Q10: Study Details - Special Instructions | R10: =IF($D$2="","(select study type)",IFERROR(INDEX(Configuration!$C$3:$C$200,MATCH($D$2&"|"&Q10,Configuration!$F$3:$F$200,0)),"—")) -> (select study type) | S10: Folder Processing Checklist | T10: =IFERROR(INDEX($W$3:$W$19,MATCH($S10,$V$3:$V$19,0)),TRUE()) -> TRUE | V10: Study Details - Special Instructions | W10: =IF($D$2="",TRUE(),IFERROR(INDEX(Configuration!$C$3:$C$200,MATCH($D$2&"|"&V10,Configuration!$F$3:$F$200,0))<>"No",TRUE())) -> TRUE
A11: 3 | B11: Completed FINAL Digital Compound Submission Form (CSF) | M11: =IF(NOT($T11),"☑","☐") -> ☐ | N11: =IF(NOT($T11),"N/A",IF($O11=TRUE(),"Ready","Not Ready")) -> Not Ready | Q11: Service Line Specific Checks | R11: =IF($D$2="","(select study type)",IFERROR(INDEX(Configuration!$C$3:$C$200,MATCH($D$2&"|"&Q11,Configuration!$F$3:$F$200,0)),"—")) -> (select study type) | S11: Folder Processing Checklist | T11: =IFERROR(INDEX($W$3:$W$19,MATCH($S11,$V$3:$V$19,0)),TRUE()) -> TRUE | V11: Service Line Specific Checks | W11: =IF($D$2="",TRUE(),IFERROR(INDEX(Configuration!$C$3:$C$200,MATCH($D$2&"|"&V11,Configuration!$F$3:$F$200,0))<>"No",TRUE())) -> TRUE
A12: 4 | B12: Record of FINAL Test Concentrations | M12: =IF(NOT($T12),"☑","☐") -> ☐ | N12: =IF(NOT($T12),"N/A",IF($O12=TRUE(),"Ready","Not Ready")) -> Not Ready | Q12: ADME | R12: =IF($D$2="","(select study type)",IFERROR(INDEX(Configuration!$C$3:$C$200,MATCH($D$2&"|"&Q12,Configuration!$F$3:$F$200,0)),"—")) -> (select study type) | S12: Folder Processing Checklist | T12: =IFERROR(INDEX($W$3:$W$19,MATCH($S12,$V$3:$V$19,0)),TRUE()) -> TRUE | V12: ADME | W12: =IF($D$2="",TRUE(),IFERROR(INDEX(Configuration!$C$3:$C$200,MATCH($D$2&"|"&V12,Configuration!$F$3:$F$200,0))<>"No",TRUE())) -> TRUE
B13: eCOM/ICPO Orders: Export of Compound Study Table (CST) Saved | M13: =IF(NOT($T13),"☑","☐") -> ☐ | N13: =IF(NOT($T13),"N/A",IF($O13=TRUE(),"Ready","Not Ready")) -> Not Ready | Q13: Ion Channels | R13: =IF($D$2="","(select study type)",IFERROR(INDEX(Configuration!$C$3:$C$200,MATCH($D$2&"|"&Q13,Configuration!$F$3:$F$200,0)),"—")) -> (select study type) | S13: Folder Processing Checklist | T13: =IFERROR(INDEX($W$3:$W$19,MATCH($S13,$V$3:$V$19,0)),TRUE()) -> TRUE | V13: Ion Channels | W13: =IF($D$2="",TRUE(),IFERROR(INDEX(Configuration!$C$3:$C$200,MATCH($D$2&"|"&V13,Configuration!$F$3:$F$200,0))<>"No",TRUE())) -> TRUE
B14: Other Order Types: Bottom Portion of CSF Completed | M14: =IF(NOT($T14),"☑","☐") -> ☐ | N14: =IF(NOT($T14),"N/A",IF($O14=TRUE(),"Ready","Not Ready")) -> Not Ready | Q14: BioMAP | R14: =IF($D$2="","(select study type)",IFERROR(INDEX(Configuration!$C$3:$C$200,MATCH($D$2&"|"&Q14,Configuration!$F$3:$F$200,0)),"—")) -> (select study type) | S14: Folder Processing Checklist | T14: =IFERROR(INDEX($W$3:$W$19,MATCH($S14,$V$3:$V$19,0)),TRUE()) -> TRUE | V14: BioMAP | W14: =IF($D$2="",TRUE(),IFERROR(INDEX(Configuration!$C$3:$C$200,MATCH($D$2&"|"&V14,Configuration!$F$3:$F$200,0))<>"No",TRUE())) -> TRUE
A15: 5 | B15: E-mail for Any Supporting Documentation or Special Instructions (If Applicable) | M15: =IF(NOT($T15),"☑","☐") -> ☐ | N15: =IF(NOT($T15),"N/A",IF($O15=TRUE(),"Ready","Not Ready")) -> Not Ready | Q15: Biomarkers | R15: =IF($D$2="","(select study type)",IFERROR(INDEX(Configuration!$C$3:$C$200,MATCH($D$2&"|"&Q15,Configuration!$F$3:$F$200,0)),"—")) -> (select study type) | S15: Folder Processing Checklist | T15: =IFERROR(INDEX($W$3:$W$19,MATCH($S15,$V$3:$V$19,0)),TRUE()) -> TRUE | V15: Biomarkers | W15: =IF($D$2="",TRUE(),IFERROR(INDEX(Configuration!$C$3:$C$200,MATCH($D$2&"|"&V15,Configuration!$F$3:$F$200,0))<>"No",TRUE())) -> TRUE
A16: 6 | B16: Compound Check E-mail Saved: If In-House Compounds Being Screened | M16: =IF(NOT($T16),"☑","☐") -> ☐ | N16: =IF(NOT($T16),"N/A",IF($O16=TRUE(),"Ready","Not Ready")) -> Not Ready | Q16: OncoPanel | R16: =IF($D$2="","(select study type)",IFERROR(INDEX(Configuration!$C$3:$C$200,MATCH($D$2&"|"&Q16,Configuration!$F$3:$F$200,0)),"—")) -> (select study type) | S16: Folder Processing Checklist | T16: =IFERROR(INDEX($W$3:$W$19,MATCH($S16,$V$3:$V$19,0)),TRUE()) -> TRUE | V16: OncoPanel | W16: =IF($D$2="",TRUE(),IFERROR(INDEX(Configuration!$C$3:$C$200,MATCH($D$2&"|"&V16,Configuration!$F$3:$F$200,0))<>"No",TRUE())) -> TRUE
A17: 7 | B17: Completed Study Details | M17: =IF(NOT($T17),"☑","☐") -> ☐ | N17: =IF(NOT($T17),"N/A",IF($O17=TRUE(),"Ready","Not Ready")) -> Not Ready | Q17: Biotherapeutics | R17: =IF($D$2="","(select study type)",IFERROR(INDEX(Configuration!$C$3:$C$200,MATCH($D$2&"|"&Q17,Configuration!$F$3:$F$200,0)),"—")) -> (select study type) | S17: Folder Processing Checklist | T17: =IFERROR(INDEX($W$3:$W$19,MATCH($S17,$V$3:$V$19,0)),TRUE()) -> TRUE | V17: Biotherapeutics | W17: =IF($D$2="",TRUE(),IFERROR(INDEX(Configuration!$C$3:$C$200,MATCH($D$2&"|"&V17,Configuration!$F$3:$F$200,0))<>"No",TRUE())) -> TRUE
A18: 8 | B18: FINAL Study Plan (If Applicable) | M18: =IF(NOT($T18),"☑","☐") -> ☐ | N18: =IF(NOT($T18),"N/A",IF($O18=TRUE(),"Ready","Not Ready")) -> Not Ready | Q18: After Shipment Received | R18: =IF($D$2="","(select study type)",IFERROR(INDEX(Configuration!$C$3:$C$200,MATCH($D$2&"|"&Q18,Configuration!$F$3:$F$200,0)),"—")) -> (select study type) | S18: Folder Processing Checklist | T18: =IFERROR(INDEX($W$3:$W$19,MATCH($S18,$V$3:$V$19,0)),TRUE()) -> TRUE | V18: After Shipment Received | W18: =IF($D$2="",TRUE(),IFERROR(INDEX(Configuration!$C$3:$C$200,MATCH($D$2&"|"&V18,Configuration!$F$3:$F$200,0))<>"No",TRUE())) -> TRUE
A19: 9 | B19: Prepayment Received, E-mail Saved (If Required) | M19: =IF(NOT($T19),"☑","☐") -> ☐ | N19: =IF(NOT($T19),"N/A",IF($O19=TRUE(),"Ready","Not Ready")) -> Not Ready | Q19: Comments/Notes | R19: =IF($D$2="","(select study type)",IFERROR(INDEX(Configuration!$C$3:$C$200,MATCH($D$2&"|"&Q19,Configuration!$F$3:$F$200,0)),"—")) -> (select study type) | S19: Folder Processing Checklist | T19: =IFERROR(INDEX($W$3:$W$19,MATCH($S19,$V$3:$V$19,0)),TRUE()) -> TRUE | V19: Comments/Notes | W19: =IF($D$2="",TRUE(),IFERROR(INDEX(Configuration!$C$3:$C$200,MATCH($D$2&"|"&V19,Configuration!$F$3:$F$200,0))<>"No",TRUE())) -> TRUE
A21: AX Processing Checklist | L21: Status | S21: AX Processing Checklist | T21: =IFERROR(INDEX($W$3:$W$19,MATCH($S21,$V$3:$V$19,0)),TRUE()) -> TRUE
A22: Order Confirmed | L22: Done | M22: N/A | S22: AX Processing Checklist | T22: =IFERROR(INDEX($W$3:$W$19,MATCH($S22,$V$3:$V$19,0)),TRUE()) -> TRUE
A23: 1 | B23: Quote Confirmed to Sales Order | M23: =IF(NOT($T23),"☑","☐") -> ☐ | N23: =IF(NOT($T23),"N/A",IF($O23=TRUE(),"Ready","Not Ready")) -> Not Ready | S23: AX Processing Checklist | T23: =IFERROR(INDEX($W$3:$W$19,MATCH($S23,$V$3:$V$19,0)),TRUE()) -> TRUE
A24: AX Header Setup | L24: Done | M24: N/A | S24: AX Processing Checklist | T24: =IFERROR(INDEX($W$3:$W$19,MATCH($S24,$V$3:$V$19,0)),TRUE()) -> TRUE
A25: 1 | B25: Invoicing Contact is Correct ( See Purchase Order Check Section) | M25: =IF(NOT($T25),"☑","☐") -> ☐ | N25: =IF(NOT($T25),"N/A",IF($O25=TRUE(),"Ready","Not Ready")) -> Not Ready | S25: AX Processing Checklist | T25: =IFERROR(INDEX($W$3:$W$19,MATCH($S25,$V$3:$V$19,0)),TRUE()) -> TRUE
B26: Set as 'Accounts Payable' (If Applicable - Check All eCommerce Orders) | M26: =IF(NOT($T26),"☑","☐") -> ☐ | N26: =IF(NOT($T26),"N/A",IF($O26=TRUE(),"Ready","Not Ready")) -> Not Ready | S26: AX Processing Checklist | T26: =IFERROR(INDEX($W$3:$W$19,MATCH($S26,$V$3:$V$19,0)),TRUE()) -> TRUE
A27: 2 | B27: Form of Approval is in PO Field | M27: =IF(NOT($T27),"☑","☐") -> ☐ | N27: =IF(NOT($T27),"N/A",IF($O27=TRUE(),"Ready","Not Ready")) -> Not Ready | S27: AX Processing Checklist | T27: =IFERROR(INDEX($W$3:$W$19,MATCH($S27,$V$3:$V$19,0)),TRUE()) -> TRUE
A28: 3 | B28: Study Director Assigned in AX | M28: =IF(NOT($T28),"☑","☐") -> ☐ | N28: =IF(NOT($T28),"N/A",IF($O28=TRUE(),"Ready","Not Ready")) -> Not Ready | S28: AX Processing Checklist | T28: =IFERROR(INDEX($W$3:$W$19,MATCH($S28,$V$3:$V$19,0)),TRUE()) -> TRUE
A29: CT/CST Check | L29: Done | M29: N/A | S29: CT/CST Check | T29: =IFERROR(INDEX($W$3:$W$19,MATCH($S29,$V$3:$V$19,0)),TRUE()) -> TRUE
A30: 1 | B30: Compound Table and Compound Study Table (CT/CST) Completed in AX | M30: =IF(NOT($T30),"☑","☐") -> ☐ | N30: =IF(NOT($T30),"N/A",IF($O30=TRUE(),"Ready","Not Ready")) -> Not Ready | S30: CT/CST Check | T30: =IFERROR(INDEX($W$3:$W$19,MATCH($S30,$V$3:$V$19,0)),TRUE()) -> TRUE
B31: Specific Compound/Assay association (not all compounds will be tested in all assays), 2nd ck required Initials: | M31: =IF(NOT($T31),"☑","☐") -> ☐ | N31: =IF(NOT($T31),"N/A",IF($O31=TRUE(),"Ready","Not Ready")) -> Not Ready | S31: CT/CST Check | T31: =IFERROR(INDEX($W$3:$W$19,MATCH($S31,$V$3:$V$19,0)),TRUE()) -> TRUE
A32: 2 | B32: Number of Compounds in CT/CST Matches Quote and Compound Submission Form | M32: =IF(NOT($T32),"☑","☐") -> ☐ | N32: =IF(NOT($T32),"N/A",IF($O32=TRUE(),"Ready","Not Ready")) -> Not Ready | S32: CT/CST Check | T32: =IFERROR(INDEX($W$3:$W$19,MATCH($S32,$V$3:$V$19,0)),TRUE()) -> TRUE
A33: 3 | B33: Compound ID in CT/CST Matches Compound Submission Form | M33: =IF(NOT($T33),"☑","☐") -> ☐ | N33: =IF(NOT($T33),"N/A",IF($O33=TRUE(),"Ready","Not Ready")) -> Not Ready | S33: CT/CST Check | T33: =IFERROR(INDEX($W$3:$W$19,MATCH($S33,$V$3:$V$19,0)),TRUE()) -> TRUE
A34: 4 | B34: Study Number in CT/CST Is Correct and Matches Sales Order | M34: =IF(NOT($T34),"☑","☐") -> ☐ | N34: =IF(NOT($T34),"N/A",IF($O34=TRUE(),"Ready","Not Ready")) -> Not Ready | S34: CT/CST Check | T34: =IFERROR(INDEX($W$3:$W$19,MATCH($S34,$V$3:$V$19,0)),TRUE()) -> TRUE
A35: 5 | B35: Final Concentration(s) Listed in CST Match Lower Portion of CSF or Client E-mail. | M35: =IF(NOT($T35),"☑","☐") -> ☐ | N35: =IF(NOT($T35),"N/A",IF($O35=TRUE(),"Ready","Not Ready")) -> Not Ready | S35: CT/CST Check | T35: =IFERROR(INDEX($W$3:$W$19,MATCH($S35,$V$3:$V$19,0)),TRUE()) -> TRUE
A36: 6 | B36: Number of Assay Lines in CST Matches Sales Order | M36: =IF(NOT($T36),"☑","☐") -> ☐ | N36: =IF(NOT($T36),"N/A",IF($O36=TRUE(),"Ready","Not Ready")) -> Not Ready | S36: CT/CST Check | T36: =IFERROR(INDEX($W$3:$W$19,MATCH($S36,$V$3:$V$19,0)),TRUE()) -> TRUE
A38: Document Processing Checklist | L38: Status | S38: Document Processing Checklist | T38: =IFERROR(INDEX($W$3:$W$19,MATCH($S38,$V$3:$V$19,0)),TRUE()) -> TRUE
A39: Purchase Order Check (Refer to SOP 11) PO Check-in must be be done on ALL US034 orders, whether created via eCommerce or by Lab P Client Services. | L39: Done | M39: N/A | S39: Purchase Order Check | T39: =IFERROR(INDEX($W$3:$W$19,MATCH($S39,$V$3:$V$19,0)),TRUE()) -> TRUE
A40: 1 | B40: Correct Eurofins Entity is Listed | M40: =IF(NOT($T40),"☑","☐") -> ☐ | N40: =IF(NOT($T40),"N/A",IF($O40=TRUE(),"Ready","Not Ready")) -> Not Ready | S40: Purchase Order Check | T40: =IFERROR(INDEX($W$3:$W$19,MATCH($S40,$V$3:$V$19,0)),TRUE()) -> TRUE
A41: 2 | B41: Client Business Address (Physical and E-mail) Matches AX | M41: =IF(NOT($T41),"☑","☐") -> ☐ | N41: =IF(NOT($T41),"N/A",IF($O41=TRUE(),"Ready","Not Ready")) -> Not Ready | S41: Purchase Order Check | T41: =IFERROR(INDEX($W$3:$W$19,MATCH($S41,$V$3:$V$19,0)),TRUE()) -> TRUE
B42: If Discrepant: CRM Updated, Contact Synced, AX Header Updated | M42: =IF(NOT($T42),"☑","☐") -> ☐ | N42: =IF(NOT($T42),"N/A",IF($O42=TRUE(),"Ready","Not Ready")) -> Not Ready | S42: Purchase Order Check | T42: =IFERROR(INDEX($W$3:$W$19,MATCH($S42,$V$3:$V$19,0)),TRUE()) -> TRUE
...

Sheet Master Checklist
A3: Folder Processing Checklist | L3: Status
A4: Required Documents in Final Folder | L4: Done | M4: N/A | Q4: Drop Down | R4: Display
A5: 1 | B5: Copy of Quotation (Final Version) | N5: =IF(ISBLANK(O5)*ISBLANK(P5),"Not Ready",IF(AND(O5=FALSE(),P5=FALSE()),"Not Ready","Ready")) -> Not Ready | Q5: Report Only Study | R5: Required Documents in Final Folder
A6: 2 | B6: Copy of Formal Approval (PO, signed quote/SOW, CC or eCOM order email). | N6: =IF(ISBLANK(O6)*ISBLANK(P6),"Not Ready",IF(AND(O6=FALSE(),P6=FALSE()),"Not Ready","Ready")) -> Not Ready | R6: AX Processing Checklist
B7: If formal approval is a signed quote or SOW:
B8: CS has confirmed with client that NO PO will be required. | N8: =IF(ISBLANK(O8)*ISBLANK(P8),"Not Ready",IF(AND(O8=FALSE(),P8=FALSE()),"Not Ready","Ready")) -> Not Ready
B9: The relevant e-mail has been saved to study folder titled "Attn Finance". | N9: =IF(ISBLANK(O9)*ISBLANK(P9),"Not Ready",IF(AND(O9=FALSE(),P9=FALSE()),"Not Ready","Ready")) -> Not Ready | Q9: ADME | R9: All But Ion channel, BioMAP, Biomarker, Oncopanel, Biotherapeutics
B10: If PO is NEVER REQUIRED: eLIMs Client Specification has been created. | N10: =IF(ISBLANK(O10)*ISBLANK(P10),"Not Ready",IF(AND(O10=FALSE(),P10=FALSE()),"Not Ready","Ready")) -> Not Ready | Q10: Ion Channel | R10: All But ADME, BioMAP, Biomarker, Oncopanel, Biotherapeutics
A11: 3 | B11: Completed FINAL Digital Compound Submission Form (CSF) | N11: =IF(ISBLANK(O11)*ISBLANK(P11),"Not Ready",IF(AND(O11=FALSE(),P11=FALSE()),"Not Ready","Ready")) -> Not Ready | Q11: BioMAP | R11: All But ADME ,Ion channel, Biomarker, Oncopanel, Biotherapeutics
A12: 4 | B12: Record of FINAL Test Concentrations | N12: =IF(ISBLANK(O12)*ISBLANK(P12),"Not Ready",IF(AND(O12=FALSE(),P12=FALSE()),"Not Ready","Ready")) -> Not Ready | Q12: Biomarker | R12: All But ADME, Ion channel, BioMAP, Oncopanel, Biotherapeutics
B13: eCOM/ICPO Orders: Export of Compound Study Table (CST) Saved | N13: =IF(ISBLANK(O13)*ISBLANK(P13),"Not Ready",IF(AND(O13=FALSE(),P13=FALSE()),"Not Ready","Ready")) -> Not Ready | Q13: Oncopanel | R13: All But ADME, Ion channel, BioMAP, Biomarker, Biotherapeutics
B14: Other Order Types: Bottom Portion of CSF Completed | N14: =IF(ISBLANK(O14)*ISBLANK(P14),"Not Ready",IF(AND(O14=FALSE(),P14=FALSE()),"Not Ready","Ready")) -> Not Ready | Q14: Biotherapeutics | R14: All ButADME, Ion channel, BioMAP, Biomarker, Oncopanel
A15: 5 | B15: E-mail for Any Supporting Documentation or Special Instructions (If Applicable) | N15: =IF(ISBLANK(O15)*ISBLANK(P15),"Not Ready",IF(AND(O15=FALSE(),P15=FALSE()),"Not Ready","Ready")) -> Not Ready | Q15: ADME/Ion Channel | R15: All But BioMAP, Biomarker, Oncopanel, Biotherapeutics
A16: 6 | B16: Compound Check E-mail Saved: If In-House Compounds Being Screened | N16: =IF(ISBLANK(O16)*ISBLANK(P16),"Not Ready",IF(AND(O16=FALSE(),P16=FALSE()),"Not Ready","Ready")) -> Not Ready | Q16: ADME/Biomap | R16: All But Ion channel, Biomarker, Oncopanel, Biotherapeutics
A17: 7 | B17: Completed Study Details | N17: =IF(ISBLANK(O17)*ISBLANK(P17),"Not Ready",IF(AND(O17=FALSE(),P17=FALSE()),"Not Ready","Ready")) -> Not Ready
A18: 8 | B18: FINAL Study Plan (If Applicable) | N18: =IF(ISBLANK(O18)*ISBLANK(P18),"Not Ready",IF(AND(O18=FALSE(),P18=FALSE()),"Not Ready","Ready")) -> Not Ready
A19: 9 | B19: Prepayment Received, E-mail Saved (If Required) | N19: =IF(ISBLANK(O19)*ISBLANK(P19),"Not Ready",IF(AND(O19=FALSE(),P19=FALSE()),"Not Ready","Ready")) -> Not Ready
A21: AX Processing Checklist | L21: Status
A22: Order Confirmed | L22: Done | M22: N/A
A23: 1 | B23: Quote Confirmed to Sales Order | N23: =IF(ISBLANK(O23)*ISBLANK(P23),"Not Ready",IF(AND(O23=FALSE(),P23=FALSE()),"Not Ready","Ready")) -> Not Ready
A24: AX Header Setup | L24: Done | M24: N/A
A25: 1 | B25: Invoicing Contact is Correct ( See Purchase Order Check Section) | N25: =IF(ISBLANK(O25)*ISBLANK(P25),"Not Ready",IF(AND(O25=FALSE(),P25=FALSE()),"Not Ready","Ready")) -> Not Ready
B26: Set as 'Accounts Payable' (If Applicable - Check All eCommerce Orders) | N26: =IF(ISBLANK(O26)*ISBLANK(P26),"Not Ready",IF(AND(O26=FALSE(),P26=FALSE()),"Not Ready","Ready")) -> Not Ready
A27: 2 | B27: Form of Approval is in PO Field | N27: =IF(ISBLANK(O27)*ISBLANK(P27),"Not Ready",IF(AND(O27=FALSE(),P27=FALSE()),"Not Ready","Ready")) -> Not Ready
A28: 3 | B28: Study Director Assigned in AX | N28: =IF(ISBLANK(O28)*ISBLANK(P28),"Not Ready",IF(AND(O28=FALSE(),P28=FALSE()),"Not Ready","Ready")) -> Not Ready
A29: CT/CST Check | L29: Done | M29: N/A
A30: 1 | B30: Compound Table and Compound Study Table (CT/CST) Completed in AX | N30: =IF(ISBLANK(O30)*ISBLANK(P30),"Not Ready",IF(AND(O30=FALSE(),P30=FALSE()),"Not Ready","Ready")) -> Not Ready
B31: Specific Compound/Assay association (not all compounds will be tested in all assays), 2nd ck required Initials: | N31: =IF(ISBLANK(O31)*ISBLANK(P31),"Not Ready",IF(AND(O31=FALSE(),P31=FALSE()),"Not Ready","Ready")) -> Not Ready
A32: 2 | B32: Number of Compounds in CT/CST Matches Quote and Compound Submission Form | N32: =IF(ISBLANK(O32)*ISBLANK(P32),"Not Ready",IF(AND(O32=FALSE(),P32=FALSE()),"Not Ready","Ready")) -> Not Ready
A33: 3 | B33: Compound ID in CT/CST Matches Compound Submission Form | N33: =IF(ISBLANK(O33)*ISBLANK(P33),"Not Ready",IF(AND(O33=FALSE(),P33=FALSE()),"Not Ready","Ready")) -> Not Ready
A34: 4 | B34: Study Number in CT/CST Is Correct and Matches Sales Order | N34: =IF(ISBLANK(O34)*ISBLANK(P34),"Not Ready",IF(AND(O34=FALSE(),P34=FALSE()),"Not Ready","Ready")) -> Not Ready
A35: 5 | B35: Final Concentration(s) Listed in CST Match Lower Portion of CSF or Client E-mail. | N35: =IF(ISBLANK(O35)*ISBLANK(P35),"Not Ready",IF(AND(O35=FALSE(),P35=FALSE()),"Not Ready","Ready")) -> Not Ready
A36: 6 | B36: Number of Assay Lines in CST Matches Sales Order | N36: =IF(ISBLANK(O36)*ISBLANK(P36),"Not Ready",IF(AND(O36=FALSE(),P36=FALSE()),"Not Ready","Ready")) -> Not Ready
A38: Document Processing Checklist | L38: Status
A39: Purchase Order Check (Refer to SOP 11) PO Check-in must be be done on ALL US034 orders, whether created via eCommerce or by Lab P Client Services. | L39: Done | M39: N/A
A40: 1 | B40: Correct Eurofins Entity is Listed | N40: =IF(ISBLANK(O40)*ISBLANK(P40),"Not Ready",IF(AND(O40=FALSE(),P40=FALSE()),"Not Ready","Ready")) -> Not Ready
A41: 2 | B41: Client Business Address (Physical and E-mail) Matches AX | N41: =IF(ISBLANK(O41)*ISBLANK(P41),"Not Ready",IF(AND(O41=FALSE(),P41=FALSE()),"Not Ready","Ready")) -> Not Ready
B42: If Discrepant: CRM Updated, Contact Synced, AX Header Updated | N42: =IF(ISBLANK(O42)*ISBLANK(P42),"Not Ready",IF(AND(O42=FALSE(),P42=FALSE()),"Not Ready","Ready")) -> Not Ready
A43: 3 | B43: Client Invoicing Address (Physical and E-mail) Matches AX | N43: =IF(ISBLANK(O43)*ISBLANK(P43),"Not Ready",IF(AND(O43=FALSE(),P43=FALSE()),"Not Ready","Ready")) -> Not Ready
B44: If Discrepant: CRM Updated, Contact Synced, AX Header Updated | N44: =IF(ISBLANK(O44)*ISBLANK(P44),"Not Ready",IF(AND(O44=FALSE(),P44=FALSE()),"Not Ready","Ready")) -> Not Ready
...

Sheet Configuration
A1: CONFIGURATION / MAPPING — edit here to change which sections show per study type
A2: Study Type | B2: Section | C2: Display (Yes/No) | D2: Notes / Needs Business Confirmation | F2: Key (auto) | H2: Study Type List (dropdown source)
A3: Report Only Study | B3: Folder Processing Checklist | C3: Yes | F3: Report Only Study|Folder Processing Checklist | H3: Report Only Study
A4: Report Only Study | B4: AX Processing Checklist | C4: Yes | F4: Report Only Study|AX Processing Checklist | H4: ADME
A5: Report Only Study | B5: CT/CST Check | C5: No | D5: Report Only: CT/CST check table set to N/A (report-only studies have no compounds/assays). | F5: Report Only Study|CT/CST Check | H5: Ion Channel
A6: Report Only Study | B6: Document Processing Checklist | C6: Yes | D6: Report Only: section shown because Purchase Order Check needs QC. | F6: Report Only Study|Document Processing Checklist | H6: BioMAP
A7: Report Only Study | B7: Purchase Order Check | C7: Yes | D7: Report Only: Purchase Order Check active for QC (per business). | F7: Report Only Study|Purchase Order Check | H7: Biomarker
A8: Report Only Study | B8: Compound Submission Form Check | C8: No | D8: Report Only: Compound Submission Form Check set to N/A (per business). | F8: Report Only Study|Compound Submission Form Check | H8: Oncopanel
A9: Report Only Study | B9: Study Details Check | C9: No | D9: Report Only: Study Details Check set to N/A (per business). | F9: Report Only Study|Study Details Check | H9: Biotherapeutics
A10: Report Only Study | B10: Study Details - Special Instructions | C10: Yes | D10: Report Only: Special Instructions (#3) kept active (per earlier business request). | F10: Report Only Study|Study Details - Special Instructions | H10: ADME/Ion Channel
A11: Report Only Study | B11: Service Line Specific Checks | C11: No | F11: Report Only Study|Service Line Specific Checks | H11: ADME/Biomap
A12: Report Only Study | B12: ADME | C12: No | F12: Report Only Study|ADME | H12: Other
A13: Report Only Study | B13: Ion Channels | C13: No | F13: Report Only Study|Ion Channels
A14: Report Only Study | B14: BioMAP | C14: No | F14: Report Only Study|BioMAP
A15: Report Only Study | B15: Biomarkers | C15: No | F15: Report Only Study|Biomarkers
A16: Report Only Study | B16: OncoPanel | C16: No | F16: Report Only Study|OncoPanel
A17: Report Only Study | B17: Biotherapeutics | C17: No | F17: Report Only Study|Biotherapeutics
A18: Report Only Study | B18: After Shipment Received | C18: No | F18: Report Only Study|After Shipment Received
A19: Report Only Study | B19: Comments/Notes | C19: Yes | F19: Report Only Study|Comments/Notes
A20: ADME | B20: Folder Processing Checklist | C20: Yes | F20: ADME|Folder Processing Checklist
A21: ADME | B21: AX Processing Checklist | C21: Yes | F21: ADME|AX Processing Checklist
A22: ADME | B22: CT/CST Check | C22: Yes | F22: ADME|CT/CST Check
A23: ADME | B23: Document Processing Checklist | C23: Yes | F23: ADME|Document Processing Checklist
A24: ADME | B24: Purchase Order Check | C24: Yes | F24: ADME|Purchase Order Check
... A155: ADME/Biomap | B155: Comments/Notes | C155: Yes | F155: ADME/Biomap|Comments/Notes
A156: Other | B156: Folder Processing Checklist | C156: Needs Confirmation | D156: Needs Business Confirmation: mapping for 'Other' not defined in transcript/existing file (shows all as safe default). | F156: Other|Folder Processing Checklist
A157: Other | B157: AX Processing Checklist | C157: Needs Confirmation | D157: Needs Business Confirmation: mapping for 'Other' not defined in transcript/existing file (shows all as safe default). | F157: Other|AX Processing Checklist
A158: Other | B158: CT/CST Check | C158: Needs Confirmation | D158: Needs Business Confirmation: mapping for 'Other' not defined in transcript/existing file (shows all as safe default). | F158: Other|CT/CST Check
A159: Other | B159: Document Processing Checklist | C159: Needs Confirmation | D159: Needs Business Confirmation: mapping for 'Other' not defined in transcript/existing file (shows all as safe default). | F159: Other|Document Processing Checklist
A160: Other | B160: Purchase Order Check | C160: Needs Confirmation | D160: Needs Business Confirmation: mapping for 'Other' not defined in transcript/existing file (shows all as safe default). | F160: Other|Purchase Order Check
A161: Other | B161: Compound Submission Form Check | C161: Needs Confirmation | D161: Needs Business Confirmation: mapping for 'Other' not defined in transcript/existing file (shows all as safe default). | F161: Other|Compound Submission Form Check
A162: Other | B162: Study Details Check | C162: Needs Confirmation | D162: Needs Business Confirmation: mapping for 'Other' not defined in transcript/existing file (shows all as safe default). | F162: Other|Study Details Check
A163: Other | B163: Study Details - Special Instructions | C163: Needs Confirmation | D163: Needs Business Confirmation: mapping for 'Other' not defined in transcript/existing file (shows all as safe default). | F163: Other|Study Details - Special Instructions
A164: Other | B164: Service Line Specific Checks | C164: Needs Confirmation | D164: Needs Business Confirmation: mapping for 'Other' not defined in transcript/existing file (shows all as safe default). | F164: Other|Service Line Specific Checks
A165: Other | B165: ADME | C165: Needs Confirmation | D165: Needs Business Confirmation: mapping for 'Other' not defined in transcript/existing file (shows all as safe default). | F165: Other|ADME
A166: Other | B166: Ion Channels | C166: Needs Confirmation | D166: Needs Business Confirmation: mapping for 'Other' not defined in transcript/existing file (shows all as safe default). | F166: Other|Ion Channels
A167: Other | B167: BioMAP | C167: Needs Confirmation | D167: Needs Business Confirmation: mapping for 'Other' not defined in transcript/existing file (shows all as safe default). | F167: Other|BioMAP
... A172: Other | B172: Comments/Notes | C172: Needs Confirmation | D172: Needs Business Confirmation: mapping for 'Other' not defined in transcript/existing file (shows all as safe default). | F172: Other|Comments/Notes
