Workbook

Sheet Study Checklist
A1: STUDY CHECKLIST — pick your study type, then complete only the sections shown | Q1: Sections for this selection
A2: Select Study Type / Service Line: | H2: =IF($D$2="","Select a study type to begin",IF(COUNTIF(N3:N136,"Not Ready")=0,"READY TO PROCEED","NOT READY — items still open")) -> Select a study type to begin | Q2: Section | R2: Show for selection?
A3: Folder Processing Checklist | L3: Status | Q3: Folder Processing Checklist | R3: =IF($D$2="","(select study type)",IFERROR(INDEX(Configuration!$C:$C,MATCH($D$2&"|"&Q3,Configuration!$F:$F,0)),"—")) -> (select study type) | S3: Folder Processing Checklist | T3: =IF($D$2="",TRUE(),IFERROR(INDEX(Configuration!$C:$C,MATCH($D$2&"|"&$S3,Configuration!$F:$F,0))<>"No",TRUE())) -> TRUE
A4: Required Documents in Final Folder | L4: Done | M4: N/A | Q4: AX Processing Checklist | R4: =IF($D$2="","(select study type)",IFERROR(INDEX(Configuration!$C:$C,MATCH($D$2&"|"&Q4,Configuration!$F:$F,0)),"—")) -> (select study type) | S4: Folder Processing Checklist | T4: =IF($D$2="",TRUE(),IFERROR(INDEX(Configuration!$C:$C,MATCH($D$2&"|"&$S4,Configuration!$F:$F,0))<>"No",TRUE())) -> TRUE
A5: 1 | B5: Copy of Quotation (Final Version) | N5: =IF(NOT($T5),"N/A",IF(OR($O5=TRUE(),$P5=TRUE()),"Ready","Not Ready")) -> Not Ready | P5: =IF(NOT($T5),TRUE(),FALSE()) -> FALSE | Q5: Document Processing Checklist | R5: =IF($D$2="","(select study type)",IFERROR(INDEX(Configuration!$C:$C,MATCH($D$2&"|"&Q5,Configuration!$F:$F,0)),"—")) -> (select study type) | S5: Folder Processing Checklist | T5: =IF($D$2="",TRUE(),IFERROR(INDEX(Configuration!$C:$C,MATCH($D$2&"|"&$S5,Configuration!$F:$F,0))<>"No",TRUE())) -> TRUE
A6: 2 | B6: Copy of Formal Approval (PO, signed quote/SOW, CC or eCOM order email). | N6: =IF(NOT($T6),"N/A",IF(OR($O6=TRUE(),$P6=TRUE()),"Ready","Not Ready")) -> Not Ready | P6: =IF(NOT($T6),TRUE(),FALSE()) -> FALSE | Q6: Service Line Specific Checks | R6: =IF($D$2="","(select study type)",IFERROR(INDEX(Configuration!$C:$C,MATCH($D$2&"|"&Q6,Configuration!$F:$F,0)),"—")) -> (select study type) | S6: Folder Processing Checklist | T6: =IF($D$2="",TRUE(),IFERROR(INDEX(Configuration!$C:$C,MATCH($D$2&"|"&$S6,Configuration!$F:$F,0))<>"No",TRUE())) -> TRUE
B7: If formal approval is a signed quote or SOW: | Q7: ADME | R7: =IF($D$2="","(select study type)",IFERROR(INDEX(Configuration!$C:$C,MATCH($D$2&"|"&Q7,Configuration!$F:$F,0)),"—")) -> (select study type) | S7: Folder Processing Checklist | T7: =IF($D$2="",TRUE(),IFERROR(INDEX(Configuration!$C:$C,MATCH($D$2&"|"&$S7,Configuration!$F:$F,0))<>"No",TRUE())) -> TRUE
B8: CS has confirmed with client that NO PO will be required. | N8: =IF(NOT($T8),"N/A",IF(OR($O8=TRUE(),$P8=TRUE()),"Ready","Not Ready")) -> Not Ready | P8: =IF(NOT($T8),TRUE(),FALSE()) -> FALSE | Q8: Ion Channels | R8: =IF($D$2="","(select study type)",IFERROR(INDEX(Configuration!$C:$C,MATCH($D$2&"|"&Q8,Configuration!$F:$F,0)),"—")) -> (select study type) | S8: Folder Processing Checklist | T8: =IF($D$2="",TRUE(),IFERROR(INDEX(Configuration!$C:$C,MATCH($D$2&"|"&$S8,Configuration!$F:$F,0))<>"No",TRUE())) -> TRUE
B9: The relevant e-mail has been saved to study folder titled "Attn Finance". | N9: =IF(NOT($T9),"N/A",IF(OR($O9=TRUE(),$P9=TRUE()),"Ready","Not Ready")) -> Not Ready | P9: =IF(NOT($T9),TRUE(),FALSE()) -> FALSE | Q9: BioMAP | R9: =IF($D$2="","(select study type)",IFERROR(INDEX(Configuration!$C:$C,MATCH($D$2&"|"&Q9,Configuration!$F:$F,0)),"—")) -> (select study type) | S9: Folder Processing Checklist | T9: =IF($D$2="",TRUE(),IFERROR(INDEX(Configuration!$C:$C,MATCH($D$2&"|"&$S9,Configuration!$F:$F,0))<>"No",TRUE())) -> TRUE
B10: If PO is NEVER REQUIRED: eLIMs Client Specification has been created. | N10: =IF(NOT($T10),"N/A",IF(OR($O10=TRUE(),$P10=TRUE()),"Ready","Not Ready")) -> Not Ready | P10: =IF(NOT($T10),TRUE(),FALSE()) -> FALSE | Q10: Biomarkers | R10: =IF($D$2="","(select study type)",IFERROR(INDEX(Configuration!$C:$C,MATCH($D$2&"|"&Q10,Configuration!$F:$F,0)),"—")) -> (select study type) | S10: Folder Processing Checklist | T10: =IF($D$2="",TRUE(),IFERROR(INDEX(Configuration!$C:$C,MATCH($D$2&"|"&$S10,Configuration!$F:$F,0))<>"No",TRUE())) -> TRUE
A11: 3 | B11: Completed FINAL Digital Compound Submission Form (CSF) | N11: =IF(NOT($T11),"N/A",IF(OR($O11=TRUE(),$P11=TRUE()),"Ready","Not Ready")) -> Not Ready | P11: =IF(NOT($T11),TRUE(),FALSE()) -> FALSE | Q11: OncoPanel | R11: =IF($D$2="","(select study type)",IFERROR(INDEX(Configuration!$C:$C,MATCH($D$2&"|"&Q11,Configuration!$F:$F,0)),"—")) -> (select study type) | S11: Folder Processing Checklist | T11: =IF($D$2="",TRUE(),IFERROR(INDEX(Configuration!$C:$C,MATCH($D$2&"|"&$S11,Configuration!$F:$F,0))<>"No",TRUE())) -> TRUE
A12: 4 | B12: Record of FINAL Test Concentrations | N12: =IF(NOT($T12),"N/A",IF(OR($O12=TRUE(),$P12=TRUE()),"Ready","Not Ready")) -> Not Ready | P12: =IF(NOT($T12),TRUE(),FALSE()) -> FALSE | Q12: Biotherapeutics | R12: =IF($D$2="","(select study type)",IFERROR(INDEX(Configuration!$C:$C,MATCH($D$2&"|"&Q12,Configuration!$F:$F,0)),"—")) -> (select study type) | S12: Folder Processing Checklist | T12: =IF($D$2="",TRUE(),IFERROR(INDEX(Configuration!$C:$C,MATCH($D$2&"|"&$S12,Configuration!$F:$F,0))<>"No",TRUE())) -> TRUE
B13: eCOM/ICPO Orders: Export of Compound Study Table (CST) Saved | N13: =IF(NOT($T13),"N/A",IF(OR($O13=TRUE(),$P13=TRUE()),"Ready","Not Ready")) -> Not Ready | P13: =IF(NOT($T13),TRUE(),FALSE()) -> FALSE | Q13: After Shipment Received | R13: =IF($D$2="","(select study type)",IFERROR(INDEX(Configuration!$C:$C,MATCH($D$2&"|"&Q13,Configuration!$F:$F,0)),"—")) -> (select study type) | S13: Folder Processing Checklist | T13: =IF($D$2="",TRUE(),IFERROR(INDEX(Configuration!$C:$C,MATCH($D$2&"|"&$S13,Configuration!$F:$F,0))<>"No",TRUE())) -> TRUE
B14: Other Order Types: Bottom Portion of CSF Completed | N14: =IF(NOT($T14),"N/A",IF(OR($O14=TRUE(),$P14=TRUE()),"Ready","Not Ready")) -> Not Ready | P14: =IF(NOT($T14),TRUE(),FALSE()) -> FALSE | Q14: Comments/Notes | R14: =IF($D$2="","(select study type)",IFERROR(INDEX(Configuration!$C:$C,MATCH($D$2&"|"&Q14,Configuration!$F:$F,0)),"—")) -> (select study type) | S14: Folder Processing Checklist | T14: =IF($D$2="",TRUE(),IFERROR(INDEX(Configuration!$C:$C,MATCH($D$2&"|"&$S14,Configuration!$F:$F,0))<>"No",TRUE())) -> TRUE
A15: 5 | B15: E-mail for Any Supporting Documentation or Special Instructions (If Applicable) | N15: =IF(NOT($T15),"N/A",IF(OR($O15=TRUE(),$P15=TRUE()),"Ready","Not Ready")) -> Not Ready | P15: =IF(NOT($T15),TRUE(),FALSE()) -> FALSE | S15: Folder Processing Checklist | T15: =IF($D$2="",TRUE(),IFERROR(INDEX(Configuration!$C:$C,MATCH($D$2&"|"&$S15,Configuration!$F:$F,0))<>"No",TRUE())) -> TRUE
A16: 6 | B16: Compound Check E-mail Saved: If In-House Compounds Being Screened | N16: =IF(NOT($T16),"N/A",IF(OR($O16=TRUE(),$P16=TRUE()),"Ready","Not Ready")) -> Not Ready | P16: =IF(NOT($T16),TRUE(),FALSE()) -> FALSE | S16: Folder Processing Checklist | T16: =IF($D$2="",TRUE(),IFERROR(INDEX(Configuration!$C:$C,MATCH($D$2&"|"&$S16,Configuration!$F:$F,0))<>"No",TRUE())) -> TRUE
A17: 7 | B17: Completed Study Details | N17: =IF(NOT($T17),"N/A",IF(OR($O17=TRUE(),$P17=TRUE()),"Ready","Not Ready")) -> Not Ready | P17: =IF(NOT($T17),TRUE(),FALSE()) -> FALSE | S17: Folder Processing Checklist | T17: =IF($D$2="",TRUE(),IFERROR(INDEX(Configuration!$C:$C,MATCH($D$2&"|"&$S17,Configuration!$F:$F,0))<>"No",TRUE())) -> TRUE
A18: 8 | B18: FINAL Study Plan (If Applicable) | N18: =IF(NOT($T18),"N/A",IF(OR($O18=TRUE(),$P18=TRUE()),"Ready","Not Ready")) -> Not Ready | P18: =IF(NOT($T18),TRUE(),FALSE()) -> FALSE | S18: Folder Processing Checklist | T18: =IF($D$2="",TRUE(),IFERROR(INDEX(Configuration!$C:$C,MATCH($D$2&"|"&$S18,Configuration!$F:$F,0))<>"No",TRUE())) -> TRUE
A19: 9 | B19: Prepayment Received, E-mail Saved (If Required) | N19: =IF(NOT($T19),"N/A",IF(OR($O19=TRUE(),$P19=TRUE()),"Ready","Not Ready")) -> Not Ready | P19: =IF(NOT($T19),TRUE(),FALSE()) -> FALSE | S19: Folder Processing Checklist | T19: =IF($D$2="",TRUE(),IFERROR(INDEX(Configuration!$C:$C,MATCH($D$2&"|"&$S19,Configuration!$F:$F,0))<>"No",TRUE())) -> TRUE
A21: AX Processing Checklist | L21: Status | S21: AX Processing Checklist | T21: =IF($D$2="",TRUE(),IFERROR(INDEX(Configuration!$C:$C,MATCH($D$2&"|"&$S21,Configuration!$F:$F,0))<>"No",TRUE())) -> TRUE
A22: Order Confirmed | L22: Done | M22: N/A | S22: AX Processing Checklist | T22: =IF($D$2="",TRUE(),IFERROR(INDEX(Configuration!$C:$C,MATCH($D$2&"|"&$S22,Configuration!$F:$F,0))<>"No",TRUE())) -> TRUE
A23: 1 | B23: Quote Confirmed to Sales Order | N23: =IF(NOT($T23),"N/A",IF(OR($O23=TRUE(),$P23=TRUE()),"Ready","Not Ready")) -> Not Ready | P23: =IF(NOT($T23),TRUE(),FALSE()) -> FALSE | S23: AX Processing Checklist | T23: =IF($D$2="",TRUE(),IFERROR(INDEX(Configuration!$C:$C,MATCH($D$2&"|"&$S23,Configuration!$F:$F,0))<>"No",TRUE())) -> TRUE
A24: AX Header Setup | L24: Done | M24: N/A | S24: AX Processing Checklist | T24: =IF($D$2="",TRUE(),IFERROR(INDEX(Configuration!$C:$C,MATCH($D$2&"|"&$S24,Configuration!$F:$F,0))<>"No",TRUE())) -> TRUE
A25: 1 | B25: Invoicing Contact is Correct ( See Purchase Order Check Section) | N25: =IF(NOT($T25),"N/A",IF(OR($O25=TRUE(),$P25=TRUE()),"Ready","Not Ready")) -> Not Ready | P25: =IF(NOT($T25),TRUE(),FALSE()) -> FALSE | S25: AX Processing Checklist | T25: =IF($D$2="",TRUE(),IFERROR(INDEX(Configuration!$C:$C,MATCH($D$2&"|"&$S25,Configuration!$F:$F,0))<>"No",TRUE())) -> TRUE
B26: Set as 'Accounts Payable' (If Applicable - Check All eCommerce Orders) | N26: =IF(NOT($T26),"N/A",IF(OR($O26=TRUE(),$P26=TRUE()),"Ready","Not Ready")) -> Not Ready | P26: =IF(NOT($T26),TRUE(),FALSE()) -> FALSE | S26: AX Processing Checklist | T26: =IF($D$2="",TRUE(),IFERROR(INDEX(Configuration!$C:$C,MATCH($D$2&"|"&$S26,Configuration!$F:$F,0))<>"No",TRUE())) -> TRUE
A27: 2 | B27: Form of Approval is in PO Field | N27: =IF(NOT($T27),"N/A",IF(OR($O27=TRUE(),$P27=TRUE()),"Ready","Not Ready")) -> Not Ready | P27: =IF(NOT($T27),TRUE(),FALSE()) -> FALSE | S27: AX Processing Checklist | T27: =IF($D$2="",TRUE(),IFERROR(INDEX(Configuration!$C:$C,MATCH($D$2&"|"&$S27,Configuration!$F:$F,0))<>"No",TRUE())) -> TRUE
A28: 3 | B28: Study Director Assigned in AX | N28: =IF(NOT($T28),"N/A",IF(OR($O28=TRUE(),$P28=TRUE()),"Ready","Not Ready")) -> Not Ready | P28: =IF(NOT($T28),TRUE(),FALSE()) -> FALSE | S28: AX Processing Checklist | T28: =IF($D$2="",TRUE(),IFERROR(INDEX(Configuration!$C:$C,MATCH($D$2&"|"&$S28,Configuration!$F:$F,0))<>"No",TRUE())) -> TRUE
A29: CT/CST Check | L29: Done | M29: N/A | S29: AX Processing Checklist | T29: =IF($D$2="",TRUE(),IFERROR(INDEX(Configuration!$C:$C,MATCH($D$2&"|"&$S29,Configuration!$F:$F,0))<>"No",TRUE())) -> TRUE
A30: 1 | B30: Compound Table and Compound Study Table (CT/CST) Completed in AX | N30: =IF(NOT($T30),"N/A",IF(OR($O30=TRUE(),$P30=TRUE()),"Ready","Not Ready")) -> Not Ready | P30: =IF(NOT($T30),TRUE(),FALSE()) -> FALSE | S30: AX Processing Checklist | T30: =IF($D$2="",TRUE(),IFERROR(INDEX(Configuration!$C:$C,MATCH($D$2&"|"&$S30,Configuration!$F:$F,0))<>"No",TRUE())) -> TRUE
B31: Specific Compound/Assay association (not all compounds will be tested in all assays), 2nd ck required Initials: | N31: =IF(NOT($T31),"N/A",IF(OR($O31=TRUE(),$P31=TRUE()),"Ready","Not Ready")) -> Not Ready | P31: =IF(NOT($T31),TRUE(),FALSE()) -> FALSE | S31: AX Processing Checklist | T31: =IF($D$2="",TRUE(),IFERROR(INDEX(Configuration!$C:$C,MATCH($D$2&"|"&$S31,Configuration!$F:$F,0))<>"No",TRUE())) -> TRUE
A32: 2 | B32: Number of Compounds in CT/CST Matches Quote and Compound Submission Form | N32: =IF(NOT($T32),"N/A",IF(OR($O32=TRUE(),$P32=TRUE()),"Ready","Not Ready")) -> Not Ready | P32: =IF(NOT($T32),TRUE(),FALSE()) -> FALSE | S32: AX Processing Checklist | T32: =IF($D$2="",TRUE(),IFERROR(INDEX(Configuration!$C:$C,MATCH($D$2&"|"&$S32,Configuration!$F:$F,0))<>"No",TRUE())) -> TRUE
A33: 3 | B33: Compound ID in CT/CST Matches Compound Submission Form | N33: =IF(NOT($T33),"N/A",IF(OR($O33=TRUE(),$P33=TRUE()),"Ready","Not Ready")) -> Not Ready | P33: =IF(NOT($T33),TRUE(),FALSE()) -> FALSE | S33: AX Processing Checklist | T33: =IF($D$2="",TRUE(),IFERROR(INDEX(Configuration!$C:$C,MATCH($D$2&"|"&$S33,Configuration!$F:$F,0))<>"No",TRUE())) -> TRUE
A34: 4 | B34: Study Number in CT/CST Is Correct and Matches Sales Order | N34: =IF(NOT($T34),"N/A",IF(OR($O34=TRUE(),$P34=TRUE()),"Ready","Not Ready")) -> Not Ready | P34: =IF(NOT($T34),TRUE(),FALSE()) -> FALSE | S34: AX Processing Checklist | T34: =IF($D$2="",TRUE(),IFERROR(INDEX(Configuration!$C:$C,MATCH($D$2&"|"&$S34,Configuration!$F:$F,0))<>"No",TRUE())) -> TRUE
A35: 5 | B35: Final Concentration(s) Listed in CST Match Lower Portion of CSF or Client E-mail. | N35: =IF(NOT($T35),"N/A",IF(OR($O35=TRUE(),$P35=TRUE()),"Ready","Not Ready")) -> Not Ready | P35: =IF(NOT($T35),TRUE(),FALSE()) -> FALSE | S35: AX Processing Checklist | T35: =IF($D$2="",TRUE(),IFERROR(INDEX(Configuration!$C:$C,MATCH($D$2&"|"&$S35,Configuration!$F:$F,0))<>"No",TRUE())) -> TRUE
A36: 6 | B36: Number of Assay Lines in CST Matches Sales Order | N36: =IF(NOT($T36),"N/A",IF(OR($O36=TRUE(),$P36=TRUE()),"Ready","Not Ready")) -> Not Ready | P36: =IF(NOT($T36),TRUE(),FALSE()) -> FALSE | S36: AX Processing Checklist | T36: =IF($D$2="",TRUE(),IFERROR(INDEX(Configuration!$C:$C,MATCH($D$2&"|"&$S36,Configuration!$F:$F,0))<>"No",TRUE())) -> TRUE
A38: Document Processing Checklist | L38: Status | S38: Document Processing Checklist | T38: =IF($D$2="",TRUE(),IFERROR(INDEX(Configuration!$C:$C,MATCH($D$2&"|"&$S38,Configuration!$F:$F,0))<>"No",TRUE())) -> TRUE
A39: Purchase Order Check (Refer to SOP 11) PO Check-in must be be done on ALL US034 orders, whether created via eCommerce or by Lab P Client Services. | L39: Done | M39: N/A | S39: Document Processing Checklist | T39: =IF($D$2="",TRUE(),IFERROR(INDEX(Configuration!$C:$C,MATCH($D$2&"|"&$S39,Configuration!$F:$F,0))<>"No",TRUE())) -> TRUE
A40: 1 | B40: Correct Eurofins Entity is Listed | N40: =IF(NOT($T40),"N/A",IF(OR($O40=TRUE(),$P40=TRUE()),"Ready","Not Ready")) -> Not Ready | P40: =IF(NOT($T40),TRUE(),FALSE()) -> FALSE | S40: Document Processing Checklist | T40: =IF($D$2="",TRUE(),IFERROR(INDEX(Configuration!$C:$C,MATCH($D$2&"|"&$S40,Configuration!$F:$F,0))<>"No",TRUE())) -> TRUE
A41: 2 | B41: Client Business Address (Physical and E-mail) Matches AX | N41: =IF(NOT($T41),"N/A",IF(OR($O41=TRUE(),$P41=TRUE()),"Ready","Not Ready")) -> Not Ready | P41: =IF(NOT($T41),TRUE(),FALSE()) -> FALSE | S41: Document Processing Checklist | T41: =IF($D$2="",TRUE(),IFERROR(INDEX(Configuration!$C:$C,MATCH($D$2&"|"&$S41,Configuration!$F:$F,0))<>"No",TRUE())) -> TRUE
B42: If Discrepant: CRM Updated, Contact Synced, AX Header Updated | N42: =IF(NOT($T42),"N/A",IF(OR($O42=TRUE(),$P42=TRUE()),"Ready","Not Ready")) -> Not Ready | P42: =IF(NOT($T42),TRUE(),FALSE()) -> FALSE | S42: Document Processing Checklist | T42: =IF($D$2="",TRUE(),IFERROR(INDEX(Configuration!$C:$C,MATCH($D$2&"|"&$S42,Configuration!$F:$F,0))<>"No",TRUE())) -> TRUE
...

Sheet Master Checklist
A3: Folder Processing Checklist | L3: Status
A4: Required Documents in Final Folder | L4: Done | M4: N/A | Q4: Drop Down | R4: Display
A5: 1 | B5: Copy of Quotation (Final Version) | N5: =IF(ISBLANK(O5)*ISBLANK(P5),"Not Ready",IF(AND(O5=FALSE(),P5=FALSE()),"Not Ready","Ready")) -> Not Ready | Q5: Report Only Study | R5: Required Documents in Final Folder
A6: 2 | B6: Copy of Formal Approval (PO, signed quote/SOW, CC or eCOM order email). | N6: =IF(ISBLANK(O6)*ISBLANK(P6),"Not Ready",IF(AND(O6=FALSE(),P6=FALSE()),"Not Ready","Ready")) -> Not Ready | R6: AX Processing Checklist
B7: If formal approval is a signed quote or SOW:
B8: CS has confirmed with client that NO PO will be required. | N8: =IF(ISBLANK(O8)*ISBLANK(P8),"Not Ready",IF(AND(O8=FALSE(),P8=FALSE()),"Not Ready","Ready")) -> Not Ready
B9: The relevant e-mail has been saved to study folder titled "Attn Finance". | N9: =IF(ISBLANK(O9)*ISBLANK(P9),"Not Ready",IF(AND(O9=FALSE(),P9=FALSE()),"Not Ready","Ready")) -> Not Ready | Q9: ADME | R9: All But Ion channel, BioMAP, Biomarker, Oncopanel, Biotherapeutics
B10: If PO is NEVER REQUIRED: eLIMs Client Specification has been created. | N10: =IF(ISBLANK(O10)*ISBLANK(P10),"Not Ready",IF(AND(O10=FALSE(),P10=FALSE()),"Not Ready","Ready")) -> Not Ready | Q10: Ion Channel | R10: All But ADME, BioMAP, Biomarker, Oncopanel, Biotherapeutics
A11: 3 | B11: Completed FINAL Digital Compound Submission Form (CSF) | N11: =IF(ISBLANK(O11)*ISBLANK(P11),"Not Ready",IF(AND(O11=FALSE(),P11=FALSE()),"Not Ready","Ready")) -> Not Ready | Q11: BioMAP | R11: All But ADME ,Ion channel, Biomarker, Oncopanel, Biotherapeutics
A12: 4 | B12: Record of FINAL Test Concentrations | N12: =IF(ISBLANK(O12)*ISBLANK(P12),"Not Ready",IF(AND(O12=FALSE(),P12=FALSE()),"Not Ready","Ready")) -> Not Ready | Q12: Biomarker | R12: All But ADME, Ion channel, BioMAP, Oncopanel, Biotherapeutics
B13: eCOM/ICPO Orders: Export of Compound Study Table (CST) Saved | N13: =IF(ISBLANK(O13)*ISBLANK(P13),"Not Ready",IF(AND(O13=FALSE(),P13=FALSE()),"Not Ready","Ready")) -> Not Ready | Q13: Oncopanel | R13: All But ADME, Ion channel, BioMAP, Biomarker, Biotherapeutics
B14: Other Order Types: Bottom Portion of CSF Completed | N14: =IF(ISBLANK(O14)*ISBLANK(P14),"Not Ready",IF(AND(O14=FALSE(),P14=FALSE()),"Not Ready","Ready")) -> Not Ready | Q14: Biotherapeutics | R14: All ButADME, Ion channel, BioMAP, Biomarker, Oncopanel
A15: 5 | B15: E-mail for Any Supporting Documentation or Special Instructions (If Applicable) | N15: =IF(ISBLANK(O15)*ISBLANK(P15),"Not Ready",IF(AND(O15=FALSE(),P15=FALSE()),"Not Ready","Ready")) -> Not Ready | Q15: ADME/Ion Channel | R15: All But BioMAP, Biomarker, Oncopanel, Biotherapeutics
A16: 6 | B16: Compound Check E-mail Saved: If In-House Compounds Being Screened | N16: =IF(ISBLANK(O16)*ISBLANK(P16),"Not Ready",IF(AND(O16=FALSE(),P16=FALSE()),"Not Ready","Ready")) -> Not Ready | Q16: ADME/Biomap | R16: All But Ion channel, Biomarker, Oncopanel, Biotherapeutics
A17: 7 | B17: Completed Study Details | N17: =IF(ISBLANK(O17)*ISBLANK(P17),"Not Ready",IF(AND(O17=FALSE(),P17=FALSE()),"Not Ready","Ready")) -> Not Ready
A18: 8 | B18: FINAL Study Plan (If Applicable) | N18: =IF(ISBLANK(O18)*ISBLANK(P18),"Not Ready",IF(AND(O18=FALSE(),P18=FALSE()),"Not Ready","Ready")) -> Not Ready
A19: 9 | B19: Prepayment Received, E-mail Saved (If Required) | N19: =IF(ISBLANK(O19)*ISBLANK(P19),"Not Ready",IF(AND(O19=FALSE(),P19=FALSE()),"Not Ready","Ready")) -> Not Ready
A21: AX Processing Checklist | L21: Status
A22: Order Confirmed | L22: Done | M22: N/A
A23: 1 | B23: Quote Confirmed to Sales Order | N23: =IF(ISBLANK(O23)*ISBLANK(P23),"Not Ready",IF(AND(O23=FALSE(),P23=FALSE()),"Not Ready","Ready")) -> Not Ready
A24: AX Header Setup | L24: Done | M24: N/A
A25: 1 | B25: Invoicing Contact is Correct ( See Purchase Order Check Section) | N25: =IF(ISBLANK(O25)*ISBLANK(P25),"Not Ready",IF(AND(O25=FALSE(),P25=FALSE()),"Not Ready","Ready")) -> Not Ready
B26: Set as 'Accounts Payable' (If Applicable - Check All eCommerce Orders) | N26: =IF(ISBLANK(O26)*ISBLANK(P26),"Not Ready",IF(AND(O26=FALSE(),P26=FALSE()),"Not Ready","Ready")) -> Not Ready
A27: 2 | B27: Form of Approval is in PO Field | N27: =IF(ISBLANK(O27)*ISBLANK(P27),"Not Ready",IF(AND(O27=FALSE(),P27=FALSE()),"Not Ready","Ready")) -> Not Ready
A28: 3 | B28: Study Director Assigned in AX | N28: =IF(ISBLANK(O28)*ISBLANK(P28),"Not Ready",IF(AND(O28=FALSE(),P28=FALSE()),"Not Ready","Ready")) -> Not Ready
A29: CT/CST Check | L29: Done | M29: N/A
A30: 1 | B30: Compound Table and Compound Study Table (CT/CST) Completed in AX | N30: =IF(ISBLANK(O30)*ISBLANK(P30),"Not Ready",IF(AND(O30=FALSE(),P30=FALSE()),"Not Ready","Ready")) -> Not Ready
B31: Specific Compound/Assay association (not all compounds will be tested in all assays), 2nd ck required Initials: | N31: =IF(ISBLANK(O31)*ISBLANK(P31),"Not Ready",IF(AND(O31=FALSE(),P31=FALSE()),"Not Ready","Ready")) -> Not Ready
A32: 2 | B32: Number of Compounds in CT/CST Matches Quote and Compound Submission Form | N32: =IF(ISBLANK(O32)*ISBLANK(P32),"Not Ready",IF(AND(O32=FALSE(),P32=FALSE()),"Not Ready","Ready")) -> Not Ready
A33: 3 | B33: Compound ID in CT/CST Matches Compound Submission Form | N33: =IF(ISBLANK(O33)*ISBLANK(P33),"Not Ready",IF(AND(O33=FALSE(),P33=FALSE()),"Not Ready","Ready")) -> Not Ready
A34: 4 | B34: Study Number in CT/CST Is Correct and Matches Sales Order | N34: =IF(ISBLANK(O34)*ISBLANK(P34),"Not Ready",IF(AND(O34=FALSE(),P34=FALSE()),"Not Ready","Ready")) -> Not Ready
A35: 5 | B35: Final Concentration(s) Listed in CST Match Lower Portion of CSF or Client E-mail. | N35: =IF(ISBLANK(O35)*ISBLANK(P35),"Not Ready",IF(AND(O35=FALSE(),P35=FALSE()),"Not Ready","Ready")) -> Not Ready
A36: 6 | B36: Number of Assay Lines in CST Matches Sales Order | N36: =IF(ISBLANK(O36)*ISBLANK(P36),"Not Ready",IF(AND(O36=FALSE(),P36=FALSE()),"Not Ready","Ready")) -> Not Ready
A38: Document Processing Checklist | L38: Status
A39: Purchase Order Check (Refer to SOP 11) PO Check-in must be be done on ALL US034 orders, whether created via eCommerce or by Lab P Client Services. | L39: Done | M39: N/A
A40: 1 | B40: Correct Eurofins Entity is Listed | N40: =IF(ISBLANK(O40)*ISBLANK(P40),"Not Ready",IF(AND(O40=FALSE(),P40=FALSE()),"Not Ready","Ready")) -> Not Ready
A41: 2 | B41: Client Business Address (Physical and E-mail) Matches AX | N41: =IF(ISBLANK(O41)*ISBLANK(P41),"Not Ready",IF(AND(O41=FALSE(),P41=FALSE()),"Not Ready","Ready")) -> Not Ready
B42: If Discrepant: CRM Updated, Contact Synced, AX Header Updated | N42: =IF(ISBLANK(O42)*ISBLANK(P42),"Not Ready",IF(AND(O42=FALSE(),P42=FALSE()),"Not Ready","Ready")) -> Not Ready
A43: 3 | B43: Client Invoicing Address (Physical and E-mail) Matches AX | N43: =IF(ISBLANK(O43)*ISBLANK(P43),"Not Ready",IF(AND(O43=FALSE(),P43=FALSE()),"Not Ready","Ready")) -> Not Ready
B44: If Discrepant: CRM Updated, Contact Synced, AX Header Updated | N44: =IF(ISBLANK(O44)*ISBLANK(P44),"Not Ready",IF(AND(O44=FALSE(),P44=FALSE()),"Not Ready","Ready")) -> Not Ready
...

Sheet Configuration
A1: CONFIGURATION / MAPPING — edit here to change which sections show per study type
A2: Study Type | B2: Section | C2: Display (Yes/No) | D2: Notes / Needs Business Confirmation | F2: Key (auto) | H2: Study Type List (dropdown source)
A3: Report Only Study | B3: Folder Processing Checklist | C3: Yes | F3: Report Only Study|Folder Processing Checklist | H3: Report Only Study
A4: Report Only Study | B4: AX Processing Checklist | C4: Yes | F4: Report Only Study|AX Processing Checklist | H4: ADME
A5: Report Only Study | B5: Document Processing Checklist | C5: No | D5: Needs Business Confirmation: transcript mentions PO checks may be needed for Report Only; existing file lists only Folder + AX. | F5: Report Only Study|Document Processing Checklist | H5: Ion Channel
A6: Report Only Study | B6: Service Line Specific Checks | C6: No | F6: Report Only Study|Service Line Specific Checks | H6: BioMAP
A7: Report Only Study | B7: ADME | C7: No | F7: Report Only Study|ADME | H7: Biomarker
A8: Report Only Study | B8: Ion Channels | C8: No | F8: Report Only Study|Ion Channels | H8: Oncopanel
A9: Report Only Study | B9: BioMAP | C9: No | F9: Report Only Study|BioMAP | H9: Biotherapeutics
A10: Report Only Study | B10: Biomarkers | C10: No | F10: Report Only Study|Biomarkers | H10: ADME/Ion Channel
A11: Report Only Study | B11: OncoPanel | C11: No | F11: Report Only Study|OncoPanel | H11: ADME/Biomap
A12: Report Only Study | B12: Biotherapeutics | C12: No | F12: Report Only Study|Biotherapeutics | H12: Other
A13: Report Only Study | B13: After Shipment Received | C13: No | F13: Report Only Study|After Shipment Received
A14: Report Only Study | B14: Comments/Notes | C14: Yes | F14: Report Only Study|Comments/Notes
A15: ADME | B15: Folder Processing Checklist | C15: Yes | F15: ADME|Folder Processing Checklist
A16: ADME | B16: AX Processing Checklist | C16: Yes | F16: ADME|AX Processing Checklist
A17: ADME | B17: Document Processing Checklist | C17: Yes | F17: ADME|Document Processing Checklist
A18: ADME | B18: Service Line Specific Checks | C18: Yes | F18: ADME|Service Line Specific Checks
A19: ADME | B19: ADME | C19: Yes | F19: ADME|ADME
A20: ADME | B20: Ion Channels | C20: No | F20: ADME|Ion Channels
A21: ADME | B21: BioMAP | C21: No | F21: ADME|BioMAP
A22: ADME | B22: Biomarkers | C22: No | F22: ADME|Biomarkers
A23: ADME | B23: OncoPanel | C23: No | F23: ADME|OncoPanel
A24: ADME | B24: Biotherapeutics | C24: No | F24: ADME|Biotherapeutics
... A110: ADME/Biomap | B110: Comments/Notes | C110: Yes | F110: ADME/Biomap|Comments/Notes
A111: Other | B111: Folder Processing Checklist | C111: Needs Confirmation | D111: Needs Business Confirmation: mapping for 'Other' not defined in transcript/existing file (shows all as safe default). | F111: Other|Folder Processing Checklist
A112: Other | B112: AX Processing Checklist | C112: Needs Confirmation | D112: Needs Business Confirmation: mapping for 'Other' not defined in transcript/existing file (shows all as safe default). | F112: Other|AX Processing Checklist
A113: Other | B113: Document Processing Checklist | C113: Needs Confirmation | D113: Needs Business Confirmation: mapping for 'Other' not defined in transcript/existing file (shows all as safe default). | F113: Other|Document Processing Checklist
A114: Other | B114: Service Line Specific Checks | C114: Needs Confirmation | D114: Needs Business Confirmation: mapping for 'Other' not defined in transcript/existing file (shows all as safe default). | F114: Other|Service Line Specific Checks
A115: Other | B115: ADME | C115: Needs Confirmation | D115: Needs Business Confirmation: mapping for 'Other' not defined in transcript/existing file (shows all as safe default). | F115: Other|ADME
A116: Other | B116: Ion Channels | C116: Needs Confirmation | D116: Needs Business Confirmation: mapping for 'Other' not defined in transcript/existing file (shows all as safe default). | F116: Other|Ion Channels
A117: Other | B117: BioMAP | C117: Needs Confirmation | D117: Needs Business Confirmation: mapping for 'Other' not defined in transcript/existing file (shows all as safe default). | F117: Other|BioMAP
A118: Other | B118: Biomarkers | C118: Needs Confirmation | D118: Needs Business Confirmation: mapping for 'Other' not defined in transcript/existing file (shows all as safe default). | F118: Other|Biomarkers
A119: Other | B119: OncoPanel | C119: Needs Confirmation | D119: Needs Business Confirmation: mapping for 'Other' not defined in transcript/existing file (shows all as safe default). | F119: Other|OncoPanel
A120: Other | B120: Biotherapeutics | C120: Needs Confirmation | D120: Needs Business Confirmation: mapping for 'Other' not defined in transcript/existing file (shows all as safe default). | F120: Other|Biotherapeutics
A121: Other | B121: After Shipment Received | C121: Needs Confirmation | D121: Needs Business Confirmation: mapping for 'Other' not defined in transcript/existing file (shows all as safe default). | F121: Other|After Shipment Received
A122: Other | B122: Comments/Notes | C122: Needs Confirmation | D122: Needs Business Confirmation: mapping for 'Other' not defined in transcript/existing file (shows all as safe default). | F122: Other|Comments/Notes
